Workbook
Name North_Operation: tbl_Requirements2[Requirement]
Name North_Service: tbl_Requirements1[Requirement]
Name Slicer_Department: #N/A
Name Slicer_Frequancy: #N/A
Name Slicer_Requirement1: #N/A
Name South_Operation: tbl_Requirements2[Requirement]
Name South_Service: tbl_Requirements1[Requirement]

Sheet Lists
B1: رجاء عدم التعديل في أسماء الاعمدة يمكنك اضافة بيانات او التعديل على البيانات الموجودة في كل جدول | E1: North/South service
A3: # | B3: Requirement | C3: # | D3: Weekly Tasks | E3: # | F3: Monthly Tasks | G3: # | H3: Quartarly Tasks | K3: # | L3: Department | M3: Manager | P3: Year | Q3: Month | R3: Group | S3: Quarter | T3: Week | U3: Frequancy | V3: Check
A4: 1 | B4: SSSV | C4: 1 | D4: Chemical Inventory | E4: 1 | F4: Fire Monitor & Hose Reel | G4: 1 | H4: Hoist Crane | K4: 1 | L4: South_Service | M4: Amri, Abdulrahman A | P4: 2025 | Q4: January | R4: A | S4: 1st Quarter | T4: WK-1 | U4: Weekly | V4: TRUE
A5: 2 | B5: SSV | C5: 2 | D5: SCABA Practice | E5: 2 | F5: Scraper PZV & Car Seal | G5: 2 | H5: Wind Sock | K5: 2 | L5: North_Service | M5: Ghamdi, Anas K | P5: 2026 | Q5: February | R5: B | S5: 2nd Quarter | T5: WK-2 | U5: Monthly | V5: FALSE
A6: 3 | B6: WELI | C6: 3 | D6: SCABA Inspection | E6: 3 | F6: Scraper Area Checklist | G6: 3 | K6: 3 | L6: South_Operation | M6: Fuazan, Fawzi A | P6: 2027 | Q6: March | R6: C | S6: 3rd Quarter | T6: WK-3 | U6: Quarterly
A7: 4 | B7: WHIT/WHGR | C7: 4 | D7: Safety Communication Meeting | E7: 4 | G7: 4 | K7: 4 | L7: North_Operation | M7: Katheeri, Khalled A | P7: 2028 | Q7: April | S7: 4th Quarter | T7: WK-4
A8: 5 | B8: ANNLI | C8: 5 | E8: 5 | G8: 5 | P8: 2029 | Q8: May | T8: WK-5
A9: 6 | B9: ANSI | C9: 6 | E9: 6 | G9: 6 | P9: 2030 | Q9: June | T9: WK-6
A10: 7 | B10: Scraper | C10: 7 | E10: 7 | G10: 7 | P10: 2031 | Q10: July | T10: WK-7
A11: 8 | C11: 8 | E11: 8 | G11: 8 | P11: 2032 | Q11: August | T11: WK-8
A12: 9 | C12: 9 | E12: 9 | G12: 9 | P12: 2033 | Q12: September | T12: WK-9
A13: 10 | C13: 10 | E13: 10 | G13: 10 | P13: 2034 | Q13: October | T13: WK-10
P14: 2035 | Q14: November | T14: WK-11
P15: 2036 | Q15: December | T15: WK-12
P16: 2037 | T16: WK-13
P17: 2038 | T17: WK-14
P18: 2039 | T18: WK-15
P19: 2040 | T19: WK-16
T20: WK-17
T21: WK-18
T22: WK-19
T23: WK-20
T24: WK-21
T25: WK-22
T26: WK-23
T27: WK-24
E28: North/South Operation | T28: WK-25
T29: WK-26
T30: WK-27
A31: # | B31: Requirement | C31: # | D31: Weekly Tasks | E31: # | F31: Monthly Tasks | G31: # | H31: Quartarly Tasks | T31: WK-28
A32: 1 | B32: ICV Stroking | C32: 1 | D32: Chemical Inventory | E32: 1 | F32: FIRE EXTINGUISHERS & HOSE REEL | G32: 1 | H32: EMERGENCY DRILL | T32: WK-29
A33: 2 | B33: PDHMS | C33: 2 | D33: SCABA Practice | E33: 2 | F33: FIRE DETECTION & ALARM SYSTEIM | G33: 2 | T33: WK-30
A34: 3 | B34: Well Testing | C34: 3 | D34: SCABA Inspection | E34: 3 | F34: H2S & LEL | G34: 3 | T34: WK-31
A35: 4 | C35: 4 | D35: Safety Communication Meeting | E35: 4 | F35: Emergency Light | G35: 4 | T35: WK-32
A36: 5 | C36: 5 | D36: CIS Checklist | E36: 5 | F36: MPFM | G36: 5 | T36: WK-33
A37: 6 | C37: 6 | E37: 6 | F37: LOTO | G37: 6 | T37: WK-34
A38: 7 | C38: 7 | E38: 7 | F38: CHEMICAL RV | G38: 7 | T38: WK-35
A39: 8 | C39: 8 | E39: 8 | F39: CAR SEAL IMPLEMENTION | G39: 8 | T39: WK-36
A40: 9 | C40: 9 | E40: 9 | F40: SAB CHECKLIST | G40: 9 | T40: WK-37
A41: 10 | C41: 10 | E41: 10 | G41: 10 | T41: WK-38
...

Sheet Total Annual Points
B1: Total Annual Points
B4: Department | C4: Requirement | D4: Year | E4: Month(Update) | F4: Total Annual Points | G4: Notes
B5: North_Operation | C5: ICV Stroking | D5: 2025
B6: North_Operation | C6: PDHMS | D6: 2025
B7: North_Operation | C7: Well Testing | D7: 2025
B8: North_Service | C8: SSSV | D8: 2025
B9: North_Service | C9: SSV | D9: 2025
B10: North_Service | C10: WELI | D10: 2025
B11: North_Service | C11: WHIT/WHGR | D11: 2025
B12: North_Service | C12: ANNLI | D12: 2025
B13: North_Service | C13: ANSI | D13: 2025
B14: North_Service | C14: Scraper | D14: 2025
B15: South_Operation | C15: ICV Stroking | D15: 2025
B16: South_Operation | C16: PDHMS | D16: 2025
... B24: South_Service | C24: Scraper | D24: 2025

Sheet South_Service
S2: =IFERROR(VLOOKUP(E16, Lists!$L$4:$M$7, 2, FALSE), "") -> Amri, Abdulrahman A
S3: ="South_Service" -> South_Service
E15: Department | F15: Manager | G15: Requirement | H15: Year | I15: Month | J15: Total Annual Points | K15: Monthly Target | L15: Completed | M15: Pending | N15: Notes | AC15: Department | AD15: Manager | AE15: Task | AF15: Frequancy | AG15: Period | AH15: Group | AI15: Completed (✔/✖) | AJ15: Notes | BA15: Department | BB15: Manager | BC15: Task | BD15: Frequancy | BE15: Period | BF15: Group | BG15: Completed (✔/✖) | BH15: Notes | BW15: Department | BX15: Manager | BY15: Task | BZ15: Frequancy | CA15: Period | CB15: Group | CC15: Completed (✔/✖) | CD15: Notes
E16: =$S$3 -> South_Service | F16: =IFERROR(VLOOKUP(SSR[[#This Row],[Department]], Lists!$L$4:$M$7, 2, FALSE), "") -> Amri, Abdulrahman A | G16: ANNLI | H16: 2025 | I16: January | J16: {=IFERROR( LOOKUP( 2,1/( ('Total Annual Points'!$B$5:$B$1000=E16)* ('Total Annual Points'!$C$5:$C$1000=G16)* ('Total Annual Points'!$D$5:$D$1000=H16)* (MATCH('Total Annual Points'!$E$5:$E$1000,{"January","February","March","April","May","June","July","August","September","October","November","December"},0) <=MATCH(I16,{"January","February","March","April","May","June","July","August","September","October","November","December"},0)) ), 'Total Annual Points'!$F$5:$F$1000 ), "")} | M16: =South_Service!$K16-South_Service!$L16 -> 0 | AC16: =$S$3 -> South_Service | AD16: =IFERROR(VLOOKUP(SSW[[#This Row],[Department]], Lists!$L$4:$M$7, 2, FALSE), "") -> Amri, Abdulrahman A | AE16: Chemical Inventory | AF16: Weekly | AG16: WK-1 | AH16: A | AI16: FALSE | BA16: =$S$3 -> South_Service | BB16: =IFERROR(VLOOKUP(SSM[[#This Row],[Department]], Lists!$L$4:$M$7, 2, FALSE), "") -> Amri, Abdulrahman A | BC16: Fire Monitor & Hose Reel | BD16: Monthly | BE16: January | BF16: A | BG16: FALSE | BW16: =$S$3 -> South_Service | BX16: =IFERROR(VLOOKUP(SSQ[[#This Row],[Department]], Lists!$L$4:$M$7, 2, FALSE), "") -> Amri, Abdulrahman A | BY16: Hoist Crane | BZ16: Quarterly | CA16: 1st Quarter | CB16: A | CC16: FALSE
E17: =$S$3 -> South_Service | F17: =IFERROR(VLOOKUP(SSR[[#This Row],[Department]], Lists!$L$4:$M$7, 2, FALSE), "") -> Amri, Abdulrahman A | G17: ANNLI | H17: 2025 | I17: February | J17: {=IFERROR( LOOKUP( 2,1/( ('Total Annual Points'!$B$5:$B$1000=E17)* ('Total Annual Points'!$C$5:$C$1000=G17)* ('Total Annual Points'!$D$5:$D$1000=H17)* (MATCH('Total Annual Points'!$E$5:$E$1000,{"January","February","March","April","May","June","July","August","September","October","November","December"},0) <=MATCH(I17,{"January","February","March","April","May","June","July","August","September","October","November","December"},0)) ), 'Total Annual Points'!$F$5:$F$1000 ), "")} | M17: =South_Service!$K17-South_Service!$L17 -> 0 | AC17: =$S$3 -> South_Service | AD17: =IFERROR(VLOOKUP(SSW[[#This Row],[Department]], Lists!$L$4:$M$7, 2, FALSE), "") -> Amri, Abdulrahman A | AE17: Chemical Inventory | AF17: Weekly | AG17: WK-2 | AH17: B | AI17: FALSE | BA17: =$S$3 -> South_Service | BB17: =IFERROR(VLOOKUP(SSM[[#This Row],[Department]], Lists!$L$4:$M$7, 2, FALSE), "") -> Amri, Abdulrahman A | BC17: Fire Monitor & Hose Reel | BD17: Monthly | BE17: February | BF17: B | BG17: FALSE | BW17: =$S$3 -> South_Service | BX17: =IFERROR(VLOOKUP(SSQ[[#This Row],[Department]], Lists!$L$4:$M$7, 2, FALSE), "") -> Amri, Abdulrahman A | BY17: Hoist Crane | BZ17: Quarterly | CA17: 2nd Quarter | CB17: B | CC17: FALSE
E18: =$S$3 -> South_Service | F18: =IFERROR(VLOOKUP(SSR[[#This Row],[Department]], Lists!$L$4:$M$7, 2, FALSE), "") -> Amri, Abdulrahman A | G18: ANNLI | H18: 2025 | I18: March | J18: {=IFERROR( LOOKUP( 2,1/( ('Total Annual Points'!$B$5:$B$1000=E18)* ('Total Annual Points'!$C$5:$C$1000=G18)* ('Total Annual Points'!$D$5:$D$1000=H18)* (MATCH('Total Annual Points'!$E$5:$E$1000,{"January","February","March","April","May","June","July","August","September","October","November","December"},0) <=MATCH(I18,{"January","February","March","April","May","June","July","August","September","October","November","December"},0)) ), 'Total Annual Points'!$F$5:$F$1000 ), "")} | M18: =South_Service!$K18-South_Service!$L18 -> 0 | AC18: =$S$3 -> South_Service | AD18: =$S$2 -> Amri, Abdulrahman A | AE18: Chemical Inventory | AF18: Weekly | AG18: WK-3 | AH18: C | AI18: FALSE | BA18: =$S$3 -> South_Service | BB18: =IFERROR(VLOOKUP(SSM[[#This Row],[Department]], Lists!$L$4:$M$7, 2, FALSE), "") -> Amri, Abdulrahman A | BC18: Fire Monitor & Hose Reel | BD18: Monthly | BE18: March | BF18: C | BG18: FALSE | BW18: =$S$3 -> South_Service | BX18: =IFERROR(VLOOKUP(SSQ[[#This Row],[Department]], Lists!$L$4:$M$7, 2, FALSE), "") -> Amri, Abdulrahman A | BY18: Hoist Crane | BZ18: Quarterly | CA18: 3rd Quarter | CB18: C | CC18: FALSE
E19: =$S$3 -> South_Service | F19: =IFERROR(VLOOKUP(SSR[[#This Row],[Department]], Lists!$L$4:$M$7, 2, FALSE), "") -> Amri, Abdulrahman A | G19: ANNLI | H19: 2025 | I19: April | J19: {=IFERROR( LOOKUP( 2,1/( ('Total Annual Points'!$B$5:$B$1000=E19)* ('Total Annual Points'!$C$5:$C$1000=G19)* ('Total Annual Points'!$D$5:$D$1000=H19)* (MATCH('Total Annual Points'!$E$5:$E$1000,{"January","February","March","April","May","June","July","August","September","October","November","December"},0) <=MATCH(I19,{"January","February","March","April","May","June","July","August","September","October","November","December"},0)) ), 'Total Annual Points'!$F$5:$F$1000 ), "")} | M19: =South_Service!$K19-South_Service!$L19 -> 0 | AC19: =$S$3 -> South_Service | AD19: =IFERROR(VLOOKUP(SSW[[#This Row],[Department]], Lists!$L$4:$M$7, 2, FALSE), "") -> Amri, Abdulrahman A | AE19: Chemical Inventory | AF19: Weekly | AG19: WK-4 | AH19: A | AI19: FALSE | BA19: =$S$3 -> South_Service | BB19: =IFERROR(VLOOKUP(SSM[[#This Row],[Department]], Lists!$L$4:$M$7, 2, FALSE), "") -> Amri, Abdulrahman A | BC19: Fire Monitor & Hose Reel | BD19: Monthly | BE19: April | BF19: A | BG19: FALSE | BW19: =$S$3 -> South_Service | BX19: =IFERROR(VLOOKUP(SSQ[[#This Row],[Department]], Lists!$L$4:$M$7, 2, FALSE), "") -> Amri, Abdulrahman A | BY19: Hoist Crane | BZ19: Quarterly | CA19: 4th Quarter | CB19: A | CC19: FALSE
E20: =$S$3 -> South_Service | F20: =IFERROR(VLOOKUP(SSR[[#This Row],[Department]], Lists!$L$4:$M$7, 2, FALSE), "") -> Amri, Abdulrahman A | G20: ANNLI | H20: 2025 | I20: May | J20: {=IFERROR( LOOKUP( 2,1/( ('Total Annual Points'!$B$5:$B$1000=E20)* ('Total Annual Points'!$C$5:$C$1000=G20)* ('Total Annual Points'!$D$5:$D$1000=H20)* (MATCH('Total Annual Points'!$E$5:$E$1000,{"January","February","March","April","May","June","July","August","September","October","November","December"},0) <=MATCH(I20,{"January","February","March","April","May","June","July","August","September","October","November","December"},0)) ), 'Total Annual Points'!$F$5:$F$1000 ), "")} | M20: =South_Service!$K20-South_Service!$L20 -> 0 | AC20: =$S$3 -> South_Service | AD20: =IFERROR(VLOOKUP(SSW[[#This Row],[Department]], Lists!$L$4:$M$7, 2, FALSE), "") -> Amri, Abdulrahman A | AE20: Chemical Inventory | AF20: Weekly | AG20: WK-5 | AH20: B | AI20: FALSE | BA20: =$S$3 -> South_Service | BB20: =IFERROR(VLOOKUP(SSM[[#This Row],[Department]], Lists!$L$4:$M$7, 2, FALSE), "") -> Amri, Abdulrahman A | BC20: Fire Monitor & Hose Reel | BD20: Monthly | BE20: May | BF20: B | BG20: FALSE | BW20: =$S$3 -> South_Service | BX20: =IFERROR(VLOOKUP(SSQ[[#This Row],[Department]], Lists!$L$4:$M$7, 2, FALSE), "") -> Amri, Abdulrahman A | BY20: Wind Sock | BZ20: Quarterly | CA20: 1st Quarter | CB20: A | CC20: FALSE
E21: =$S$3 -> South_Service | F21: =IFERROR(VLOOKUP(SSR[[#This Row],[Department]], Lists!$L$4:$M$7, 2, FALSE), "") -> Amri, Abdulrahman A | G21: ANNLI | H21: 2025 | I21: June | J21: {=IFERROR( LOOKUP( 2,1/( ('Total Annual Points'!$B$5:$B$1000=E21)* ('Total Annual Points'!$C$5:$C$1000=G21)* ('Total Annual Points'!$D$5:$D$1000=H21)* (MATCH('Total Annual Points'!$E$5:$E$1000,{"January","February","March","April","May","June","July","August","September","October","November","December"},0) <=MATCH(I21,{"January","February","March","April","May","June","July","August","September","October","November","December"},0)) ), 'Total Annual Points'!$F$5:$F$1000 ), "")} | M21: =South_Service!$K21-South_Service!$L21 -> 0 | AC21: =$S$3 -> South_Service | AD21: =IFERROR(VLOOKUP(SSW[[#This Row],[Department]], Lists!$L$4:$M$7, 2, FALSE), "") -> Amri, Abdulrahman A | AE21: Chemical Inventory | AF21: Weekly | AG21: WK-6 | AH21: C | AI21: FALSE | BA21: =$S$3 -> South_Service | BB21: =IFERROR(VLOOKUP(SSM[[#This Row],[Department]], Lists!$L$4:$M$7, 2, FALSE), "") -> Amri, Abdulrahman A | BC21: Fire Monitor & Hose Reel | BD21: Monthly | BE21: June | BF21: C | BG21: FALSE | BW21: =$S$3 -> South_Service | BX21: =IFERROR(VLOOKUP(SSQ[[#This Row],[Department]], Lists!$L$4:$M$7, 2, FALSE), "") -> Amri, Abdulrahman A | BY21: Wind Sock | BZ21: Quarterly | CA21: 2nd Quarter | CB21: B | CC21: FALSE
E22: =$S$3 -> South_Service | F22: =IFERROR(VLOOKUP(SSR[[#This Row],[Department]], Lists!$L$4:$M$7, 2, FALSE), "") -> Amri, Abdulrahman A | G22: ANNLI | H22: 2025 | I22: July | J22: {=IFERROR( LOOKUP( 2,1/( ('Total Annual Points'!$B$5:$B$1000=E22)* ('Total Annual Points'!$C$5:$C$1000=G22)* ('Total Annual Points'!$D$5:$D$1000=H22)* (MATCH('Total Annual Points'!$E$5:$E$1000,{"January","February","March","April","May","June","July","August","September","October","November","December"},0) <=MATCH(I22,{"January","February","March","April","May","June","July","August","September","October","November","December"},0)) ), 'Total Annual Points'!$F$5:$F$1000 ), "")} | M22: =South_Service!$K22-South_Service!$L22 -> 0 | AC22: =$S$3 -> South_Service | AD22: =IFERROR(VLOOKUP(SSW[[#This Row],[Department]], Lists!$L$4:$M$7, 2, FALSE), "") -> Amri, Abdulrahman A | AE22: Chemical Inventory | AF22: Weekly | AG22: WK-7 | AH22: A | AI22: FALSE | BA22: =$S$3 -> South_Service | BB22: =IFERROR(VLOOKUP(SSM[[#This Row],[Department]], Lists!$L$4:$M$7, 2, FALSE), "") -> Amri, Abdulrahman A | BC22: Fire Monitor & Hose Reel | BD22: Monthly | BE22: July | BF22: A | BG22: FALSE | BW22: =$S$3 -> South_Service | BX22: =IFERROR(VLOOKUP(SSQ[[#This Row],[Department]], Lists!$L$4:$M$7, 2, FALSE), "") -> Amri, Abdulrahman A | BY22: Wind Sock | BZ22: Quarterly | CA22: 3rd Quarter | CB22: C | CC22: FALSE
E23: =$S$3 -> South_Service | F23: =IFERROR(VLOOKUP(SSR[[#This Row],[Department]], Lists!$L$4:$M$7, 2, FALSE), "") -> Amri, Abdulrahman A | G23: ANNLI | H23: 2025 | I23: August | J23: {=IFERROR( LOOKUP( 2,1/( ('Total Annual Points'!$B$5:$B$1000=E23)* ('Total Annual Points'!$C$5:$C$1000=G23)* ('Total Annual Points'!$D$5:$D$1000=H23)* (MATCH('Total Annual Points'!$E$5:$E$1000,{"January","February","March","April","May","June","July","August","September","October","November","December"},0) <=MATCH(I23,{"January","February","March","April","May","June","July","August","September","October","November","December"},0)) ), 'Total Annual Points'!$F$5:$F$1000 ), "")} | M23: =South_Service!$K23-South_Service!$L23 -> 0 | AC23: =$S$3 -> South_Service | AD23: =IFERROR(VLOOKUP(SSW[[#This Row],[Department]], Lists!$L$4:$M$7, 2, FALSE), "") -> Amri, Abdulrahman A | AE23: Chemical Inventory | AF23: Weekly | AG23: WK-8 | AH23: B | AI23: FALSE | BA23: =$S$3 -> South_Service | BB23: =IFERROR(VLOOKUP(SSM[[#This Row],[Department]], Lists!$L$4:$M$7, 2, FALSE), "") -> Amri, Abdulrahman A | BC23: Fire Monitor & Hose Reel | BD23: Monthly | BE23: August | BF23: B | BG23: FALSE | BW23: =$S$3 -> South_Service | BX23: =IFERROR(VLOOKUP(SSQ[[#This Row],[Department]], Lists!$L$4:$M$7, 2, FALSE), "") -> Amri, Abdulrahman A | BY23: Wind Sock | BZ23: Quarterly | CA23: 4th Quarter | CB23: A | CC23: FALSE
E24: =$S$3 -> South_Service | F24: =IFERROR(VLOOKUP(SSR[[#This Row],[Department]], Lists!$L$4:$M$7, 2, FALSE), "") -> Amri, Abdulrahman A | G24: ANNLI | H24: 2025 | I24: September | J24: {=IFERROR( LOOKUP( 2,1/( ('Total Annual Points'!$B$5:$B$1000=E24)* ('Total Annual Points'!$C$5:$C$1000=G24)* ('Total Annual Points'!$D$5:$D$1000=H24)* (MATCH('Total Annual Points'!$E$5:$E$1000,{"January","February","March","April","May","June","July","August","September","October","November","December"},0) <=MATCH(I24,{"January","February","March","April","May","June","July","August","September","October","November","December"},0)) ), 'Total Annual Points'!$F$5:$F$1000 ), "")} | M24: =South_Service!$K24-South_Service!$L24 -> 0 | AC24: =$S$3 -> South_Service | AD24: =IFERROR(VLOOKUP(SSW[[#This Row],[Department]], Lists!$L$4:$M$7, 2, FALSE), "") -> Amri, Abdulrahman A | AE24: Chemical Inventory | AF24: Weekly | AG24: WK-9 | AH24: C | AI24: FALSE | BA24: =$S$3 -> South_Service | BB24: =IFERROR(VLOOKUP(SSM[[#This Row],[Department]], Lists!$L$4:$M$7, 2, FALSE), "") -> Amri, Abdulrahman A | BC24: Fire Monitor & Hose Reel | BD24: Monthly | BE24: September | BF24: C | BG24: FALSE | BW24: =$S$3 -> South_Service | BX24: =IFERROR(VLOOKUP(SSQ[[#This Row],[Department]], Lists!$L$4:$M$7, 2, FALSE), "")
E25: =$S$3 -> South_Service | F25: =IFERROR(VLOOKUP(SSR[[#This Row],[Department]], Lists!$L$4:$M$7, 2, FALSE), "") -> Amri, Abdulrahman A | G25: ANNLI | H25: 2025 | I25: October | J25: {=IFERROR( LOOKUP( 2,1/( ('Total Annual Points'!$B$5:$B$1000=E25)* ('Total Annual Points'!$C$5:$C$1000=G25)* ('Total Annual Points'!$D$5:$D$1000=H25)* (MATCH('Total Annual Points'!$E$5:$E$1000,{"January","February","March","April","May","June","July","August","September","October","November","December"},0) <=MATCH(I25,{"January","February","March","April","May","June","July","August","September","October","November","December"},0)) ), 'Total Annual Points'!$F$5:$F$1000 ), "")} | M25: =South_Service!$K25-South_Service!$L25 -> 0 | AC25: =$S$3 -> South_Service | AD25: =IFERROR(VLOOKUP(SSW[[#This Row],[Department]], Lists!$L$4:$M$7, 2, FALSE), "") -> Amri, Abdulrahman A | AE25: Chemical Inventory | AF25: Weekly | AG25: WK-10 | AH25: A | AI25: FALSE | BA25: =$S$3 -> South_Service | BB25: =IFERROR(VLOOKUP(SSM[[#This Row],[Department]], Lists!$L$4:$M$7, 2, FALSE), "") -> Amri, Abdulrahman A | BC25: Fire Monitor & Hose Reel | BD25: Monthly | BE25: October | BF25: A | BG25: FALSE | BW25: =$S$3 -> South_Service | BX25: =IFERROR(VLOOKUP(SSQ[[#This Row],[Department]], Lists!$L$4:$M$7, 2, FALSE), "")
E26: =$S$3 -> South_Service | F26: =IFERROR(VLOOKUP(SSR[[#This Row],[Department]], Lists!$L$4:$M$7, 2, FALSE), "") -> Amri, Abdulrahman A | G26: ANNLI | H26: 2025 | I26: November | J26: {=IFERROR( LOOKUP( 2,1/( ('Total Annual Points'!$B$5:$B$1000=E26)* ('Total Annual Points'!$C$5:$C$1000=G26)* ('Total Annual Points'!$D$5:$D$1000=H26)* (MATCH('Total Annual Points'!$E$5:$E$1000,{"January","February","March","April","May","June","July","August","September","October","November","December"},0) <=MATCH(I26,{"January","February","March","April","May","June","July","August","September","October","November","December"},0)) ), 'Total Annual Points'!$F$5:$F$1000 ), "")} | M26: =South_Service!$K26-South_Service!$L26 -> 0 | AC26: =$S$3 -> South_Service | AD26: =IFERROR(VLOOKUP(SSW[[#This Row],[Department]], Lists!$L$4:$M$7, 2, FALSE), "") -> Amri, Abdulrahman A | AE26: Chemical Inventory | AF26: Weekly | AG26: WK-11 | AH26: B | AI26: FALSE | BA26: =$S$3 -> South_Service | BB26: =IFERROR(VLOOKUP(SSM[[#This Row],[Department]], Lists!$L$4:$M$7, 2, FALSE), "") -> Amri, Abdulrahman A | BC26: Fire Monitor & Hose Reel | BD26: Monthly | BE26: November | BF26: B | BG26: FALSE | BW26: =$S$3 -> South_Service | BX26: =IFERROR(VLOOKUP(SSQ[[#This Row],[Department]], Lists!$L$4:$M$7, 2, FALSE), "")
E27: =$S$3 -> South_Service | F27: =IFERROR(VLOOKUP(SSR[[#This Row],[Department]], Lists!$L$4:$M$7, 2, FALSE), "") -> Amri, Abdulrahman A | G27: ANNLI | H27: 2025 | I27: December | J27: {=IFERROR( LOOKUP( 2,1/( ('Total Annual Points'!$B$5:$B$1000=E27)* ('Total Annual Points'!$C$5:$C$1000=G27)* ('Total Annual Points'!$D$5:$D$1000=H27)* (MATCH('Total Annual Points'!$E$5:$E$1000,{"January","February","March","April","May","June","July","August","September","October","November","December"},0) <=MATCH(I27,{"January","February","March","April","May","June","July","August","September","October","November","December"},0)) ), 'Total Annual Points'!$F$5:$F$1000 ), "")} | M27: =South_Service!$K27-South_Service!$L27 -> 0 | AC27: =$S$3 -> South_Service | AD27: =IFERROR(VLOOKUP(SSW[[#This Row],[Department]], Lists!$L$4:$M$7, 2, FALSE), "") -> Amri, Abdulrahman A | AE27: Chemical Inventory | AF27: Weekly | AG27: WK-12 | AH27: A | AI27: FALSE | BA27: =$S$3 -> South_Service | BB27: =IFERROR(VLOOKUP(SSM[[#This Row],[Department]], Lists!$L$4:$M$7, 2, FALSE), "") -> Amri, Abdulrahman A | BC27: Fire Monitor & Hose Reel | BD27: Monthly | BE27: December | BF27: C | BG27: FALSE | BW27: =$S$3 -> South_Service | BX27: =IFERROR(VLOOKUP(SSQ[[#This Row],[Department]], Lists!$L$4:$M$7, 2, FALSE), "")
E28: =$S$3 -> South_Service | F28: =IFERROR(VLOOKUP(SSR[[#This Row],[Department]], Lists!$L$4:$M$7, 2, FALSE), "") -> Amri, Abdulrahman A | G28: ANSI | H28: 2025 | I28: January | J28: {=IFERROR( LOOKUP( 2,1/( ('Total Annual Points'!$B$5:$B$1000=E28)* ('Total Annual Points'!$C$5:$C$1000=G28)* ('Total Annual Points'!$D$5:$D$1000=H28)* (MATCH('Total Annual Points'!$E$5:$E$1000,{"January","February","March","April","May","June","July","August","September","October","November","December"},0) <=MATCH(I28,{"January","February","March","April","May","June","July","August","September","October","November","December"},0)) ), 'Total Annual Points'!$F$5:$F$1000 ), "")} | M28: =South_Service!$K28-South_Service!$L28 -> 0 | AC28: =$S$3 -> South_Service | AD28: =IFERROR(VLOOKUP(SSW[[#This Row],[Department]], Lists!$L$4:$M$7, 2, FALSE), "") -> Amri, Abdulrahman A | AE28: Chemical Inventory | AF28: Weekly | AG28: WK-13 | AH28: B | AI28: FALSE | BA28: =$S$3 -> South_Service | BB28: =IFERROR(VLOOKUP(SSM[[#This Row],[Department]], Lists!$L$4:$M$7, 2, FALSE), "") -> Amri, Abdulrahman A | BC28: Scraper Area Checklist | BD28: Monthly | BE28: January | BF28: A | BG28: FALSE | BW28: =$S$3 -> South_Service | BX28: =IFERROR(VLOOKUP(SSQ[[#This Row],[Department]], Lists!$L$4:$M$7, 2, FALSE), "")
E29: =$S$3 -> South_Service | F29: =IFERROR(VLOOKUP(SSR[[#This Row],[Department]], Lists!$L$4:$M$7, 2, FALSE), "") -> Amri, Abdulrahman A | G29: ANSI | H29: 2025 | I29: February | J29: {=IFERROR( LOOKUP( 2,1/( ('Total Annual Points'!$B$5:$B$1000=E29)* ('Total Annual Points'!$C$5:$C$1000=G29)* ('Total Annual Points'!$D$5:$D$1000=H29)* (MATCH('Total Annual Points'!$E$5:$E$1000,{"January","February","March","April","May","June","July","August","September","October","November","December"},0) <=MATCH(I29,{"January","February","March","April","May","June","July","August","September","October","November","December"},0)) ), 'Total Annual Points'!$F$5:$F$1000 ), "")} | M29: =South_Service!$K29-South_Service!$L29 -> 0 | AC29: =$S$3 -> South_Service | AD29: =IFERROR(VLOOKUP(SSW[[#This Row],[Department]], Lists!$L$4:$M$7, 2, FALSE), "") -> Amri, Abdulrahman A | AE29: Chemical Inventory | AF29: Weekly | AG29: WK-14 | AH29: C | AI29: FALSE | BA29: =$S$3 -> South_Service | BB29: =IFERROR(VLOOKUP(SSM[[#This Row],[Department]], Lists!$L$4:$M$7, 2, FALSE), "") -> Amri, Abdulrahman A | BC29: Scraper Area Checklist | BD29: Monthly | BE29: February | BF29: B | BG29: FALSE | BW29: =$S$3 -> South_Service | BX29: =IFERROR(VLOOKUP(SSQ[[#This Row],[Department]], Lists!$L$4:$M$7, 2, FALSE), "")
E30: =$S$3 -> South_Service | F30: =IFERROR(VLOOKUP(SSR[[#This Row],[Department]], Lists!$L$4:$M$7, 2, FALSE), "") -> Amri, Abdulrahman A | G30: ANSI | H30: 2025 | I30: March | J30: {=IFERROR( LOOKUP( 2,1/( ('Total Annual Points'!$B$5:$B$1000=E30)* ('Total Annual Points'!$C$5:$C$1000=G30)* ('Total Annual Points'!$D$5:$D$1000=H30)* (MATCH('Total Annual Points'!$E$5:$E$1000,{"January","February","March","April","May","June","July","August","September","October","November","December"},0) <=MATCH(I30,{"January","February","March","April","May","June","July","August","September","October","November","December"},0)) ), 'Total Annual Points'!$F$5:$F$1000 ), "")} | M30: =South_Service!$K30-South_Service!$L30 -> 0 | AC30: =$S$3 -> South_Service | AD30: =IFERROR(VLOOKUP(SSW[[#This Row],[Department]], Lists!$L$4:$M$7, 2, FALSE), "") -> Amri, Abdulrahman A | AE30: Chemical Inventory | AF30: Weekly | AG30: WK-15 | AH30: A | AI30: FALSE | BA30: =$S$3 -> South_Service | BB30: =IFERROR(VLOOKUP(SSM[[#This Row],[Department]], Lists!$L$4:$M$7, 2, FALSE), "") -> Amri, Abdulrahman A | BC30: Scraper Area Checklist | BD30: Monthly | BE30: March | BF30: C | BG30: FALSE | BW30: =$S$3 -> South_Service | BX30: =IFERROR(VLOOKUP(SSQ[[#This Row],[Department]], Lists!$L$4:$M$7, 2, FALSE), "")
E31: =$S$3 -> South_Service | F31: =IFERROR(VLOOKUP(SSR[[#This Row],[Department]], Lists!$L$4:$M$7, 2, FALSE), "") -> Amri, Abdulrahman A | G31: ANSI | H31: 2025 | I31: April | J31: {=IFERROR( LOOKUP( 2,1/( ('Total Annual Points'!$B$5:$B$1000=E31)* ('Total Annual Points'!$C$5:$C$1000=G31)* ('Total Annual Points'!$D$5:$D$1000=H31)* (MATCH('Total Annual Points'!$E$5:$E$1000,{"January","February","March","April","May","June","July","August","September","October","November","December"},0) <=MATCH(I31,{"January","February","March","April","May","June","July","August","September","October","November","December"},0)) ), 'Total Annual Points'!$F$5:$F$1000 ), "")} | M31: =South_Service!$K31-South_Service!$L31 -> 0 | AC31: =$S$3 -> South_Service | AD31: =IFERROR(VLOOKUP(SSW[[#This Row],[Department]], Lists!$L$4:$M$7, 2, FALSE), "") -> Amri, Abdulrahman A | AE31: Chemical Inventory | AF31: Weekly | AG31: WK-16 | AH31: B | AI31: FALSE | BA31: =$S$3 -> South_Service | BB31: =IFERROR(VLOOKUP(SSM[[#This Row],[Department]], Lists!$L$4:$M$7, 2, FALSE), "") -> Amri, Abdulrahman A | BC31: Scraper Area Checklist | BD31: Monthly | BE31: April | BF31: A | BG31: FALSE | BW31: =$S$3 -> South_Service | BX31: =IFERROR(VLOOKUP(SSQ[[#This Row],[Department]], Lists!$L$4:$M$7, 2, FALSE), "")
E32: =$S$3 -> South_Service | F32: =IFERROR(VLOOKUP(SSR[[#This Row],[Department]], Lists!$L$4:$M$7, 2, FALSE), "") -> Amri, Abdulrahman A | G32: ANSI | H32: 2025 | I32: May | J32: {=IFERROR( LOOKUP( 2,1/( ('Total Annual Points'!$B$5:$B$1000=E32)* ('Total Annual Points'!$C$5:$C$1000=G32)* ('Total Annual Points'!$D$5:$D$1000=H32)* (MATCH('Total Annual Points'!$E$5:$E$1000,{"January","February","March","April","May","June","July","August","September","October","November","December"},0) <=MATCH(I32,{"January","February","March","April","May","June","July","August","September","October","November","December"},0)) ), 'Total Annual Points'!$F$5:$F$1000 ), "")} | M32: =South_Service!$K32-South_Service!$L32 -> 0 | AC32: =$S$3 -> South_Service | AD32: =IFERROR(VLOOKUP(SSW[[#This Row],[Department]], Lists!$L$4:$M$7, 2, FALSE), "") -> Amri, Abdulrahman A | AE32: Chemical Inventory | AF32: Weekly | AG32: WK-17 | AH32: C | AI32: FALSE | BA32: =$S$3 -> South_Service | BB32: =IFERROR(VLOOKUP(SSM[[#This Row],[Department]], Lists!$L$4:$M$7, 2, FALSE), "") -> Amri, Abdulrahman A | BC32: Scraper Area Checklist | BD32: Monthly | BE32: May | BF32: B | BG32: FALSE | BW32: =$S$3 -> South_Service | BX32: =IFERROR(VLOOKUP(SSQ[[#This Row],[Department]], Lists!$L$4:$M$7, 2, FALSE), "")
E33: =$S$3 -> South_Service | F33: =IFERROR(VLOOKUP(SSR[[#This Row],[Department]], Lists!$L$4:$M$7, 2, FALSE), "") -> Amri, Abdulrahman A | G33: ANSI | H33: 2025 | I33: June | J33: {=IFERROR( LOOKUP( 2,1/( ('Total Annual Points'!$B$5:$B$1000=E33)* ('Total Annual Points'!$C$5:$C$1000=G33)* ('Total Annual Points'!$D$5:$D$1000=H33)* (MATCH('Total Annual Points'!$E$5:$E$1000,{"January","February","March","April","May","June","July","August","September","October","November","December"},0) <=MATCH(I33,{"January","February","March","April","May","June","July","August","September","October","November","December"},0)) ), 'Total Annual Points'!$F$5:$F$1000 ), "")} | M33: =South_Service!$K33-South_Service!$L33 -> 0 | AC33: =$S$3 -> South_Service | AD33: =IFERROR(VLOOKUP(SSW[[#This Row],[Department]], Lists!$L$4:$M$7, 2, FALSE), "") -> Amri, Abdulrahman A | AE33: Chemical Inventory | AF33: Weekly | AG33: WK-18 | AH33: A | AI33: FALSE | BA33: =$S$3 -> South_Service | BB33: =IFERROR(VLOOKUP(SSM[[#This Row],[Department]], Lists!$L$4:$M$7, 2, FALSE), "") -> Amri, Abdulrahman A | BC33: Scraper Area Checklist | BD33: Monthly | BE33: June | BF33: C | BG33: FALSE
E34: =$S$3 -> South_Service | F34: =IFERROR(VLOOKUP(SSR[[#This Row],[Department]], Lists!$L$4:$M$7, 2, FALSE), "") -> Amri, Abdulrahman A | G34: ANSI | H34: 2025 | I34: July | J34: {=IFERROR( LOOKUP( 2,1/( ('Total Annual Points'!$B$5:$B$1000=E34)* ('Total Annual Points'!$C$5:$C$1000=G34)* ('Total Annual Points'!$D$5:$D$1000=H34)* (MATCH('Total Annual Points'!$E$5:$E$1000,{"January","February","March","April","May","June","July","August","September","October","November","December"},0) <=MATCH(I34,{"January","February","March","April","May","June","July","August","September","October","November","December"},0)) ), 'Total Annual Points'!$F$5:$F$1000 ), "")} | M34: =South_Service!$K34-South_Service!$L34 -> 0 | AC34: =$S$3 -> South_Service | AD34: =IFERROR(VLOOKUP(SSW[[#This Row],[Department]], Lists!$L$4:$M$7, 2, FALSE), "") -> Amri, Abdulrahman A | AE34: Chemical Inventory | AF34: Weekly | AG34: WK-19 | AH34: B | AI34: FALSE | BA34: =$S$3 -> South_Service | BB34: =IFERROR(VLOOKUP(SSM[[#This Row],[Department]], Lists!$L$4:$M$7, 2, FALSE), "") -> Amri, Abdulrahman A | BC34: Scraper Area Checklist | BD34: Monthly | BE34: July | BF34: A | BG34: FALSE
E35: =$S$3 -> South_Service | F35: =IFERROR(VLOOKUP(SSR[[#This Row],[Department]], Lists!$L$4:$M$7, 2, FALSE), "") -> Amri, Abdulrahman A | G35: ANSI | H35: 2025 | I35: August | J35: {=IFERROR( LOOKUP( 2,1/( ('Total Annual Points'!$B$5:$B$1000=E35)* ('Total Annual Points'!$C$5:$C$1000=G35)* ('Total Annual Points'!$D$5:$D$1000=H35)* (MATCH('Total Annual Points'!$E$5:$E$1000,{"January","February","March","April","May","June","July","August","September","October","November","December"},0) <=MATCH(I35,{"January","February","March","April","May","June","July","August","September","October","November","December"},0)) ), 'Total Annual Points'!$F$5:$F$1000 ), "")} | M35: =South_Service!$K35-South_Service!$L35 -> 0 | AC35: =$S$3 -> South_Service | AD35: =IFERROR(VLOOKUP(SSW[[#This Row],[Department]], Lists!$L$4:$M$7, 2, FALSE), "") -> Amri, Abdulrahman A | AE35: Chemical Inventory | AF35: Weekly | AG35: WK-20 | AH35: C | AI35: FALSE | BA35: =$S$3 -> South_Service | BB35: =IFERROR(VLOOKUP(SSM[[#This Row],[Department]], Lists!$L$4:$M$7, 2, FALSE), "") -> Amri, Abdulrahman A | BC35: Scraper Area Checklist | BD35: Monthly | BE35: August | BF35: B | BG35: FALSE
E36: =$S$3 -> South_Service | F36: =IFERROR(VLOOKUP(SSR[[#This Row],[Department]], Lists!$L$4:$M$7, 2, FALSE), "") -> Amri, Abdulrahman A | G36: ANSI | H36: 2025 | I36: September | J36: {=IFERROR( LOOKUP( 2,1/( ('Total Annual Points'!$B$5:$B$1000=E36)* ('Total Annual Points'!$C$5:$C$1000=G36)* ('Total Annual Points'!$D$5:$D$1000=H36)* (MATCH('Total Annual Points'!$E$5:$E$1000,{"January","February","March","April","May","June","July","August","September","October","November","December"},0) <=MATCH(I36,{"January","February","March","April","May","June","July","August","September","October","November","December"},0)) ), 'Total Annual Points'!$F$5:$F$1000 ), "")} | M36: =South_Service!$K36-South_Service!$L36 -> 0 | AC36: =$S$3 -> South_Service | AD36: =IFERROR(VLOOKUP(SSW[[#This Row],[Department]], Lists!$L$4:$M$7, 2, FALSE), "") -> Amri, Abdulrahman A | AE36: Chemical Inventory | AF36: Weekly | AG36: WK-21 | AH36: A | AI36: FALSE | BA36: =$S$3 -> South_Service | BB36: =IFERROR(VLOOKUP(SSM[[#This Row],[Department]], Lists!$L$4:$M$7, 2, FALSE), "") -> Amri, Abdulrahman A | BC36: Scraper Area Checklist | BD36: Monthly | BE36: September | BF36: C | BG36: FALSE
E37: =$S$3 -> South_Service | F37: =IFERROR(VLOOKUP(SSR[[#This Row],[Department]], Lists!$L$4:$M$7, 2, FALSE), "") -> Amri, Abdulrahman A | G37: ANSI | H37: 2025 | I37: October | J37: {=IFERROR( LOOKUP( 2,1/( ('Total Annual Points'!$B$5:$B$1000=E37)* ('Total Annual Points'!$C$5:$C$1000=G37)* ('Total Annual Points'!$D$5:$D$1000=H37)* (MATCH('Total Annual Points'!$E$5:$E$1000,{"January","February","March","April","May","June","July","August","September","October","November","December"},0) <=MATCH(I37,{"January","February","March","April","May","June","July","August","September","October","November","December"},0)) ), 'Total Annual Points'!$F$5:$F$1000 ), "")} | M37: =South_Service!$K37-South_Service!$L37 -> 0 | AC37: =$S$3 -> South_Service | AD37: =IFERROR(VLOOKUP(SSW[[#This Row],[Department]], Lists!$L$4:$M$7, 2, FALSE), "") -> Amri, Abdulrahman A | AE37: Chemical Inventory | AF37: Weekly | AG37: WK-22 | AH37: B | AI37: FALSE | BA37: =$S$3 -> South_Service | BB37: =IFERROR(VLOOKUP(SSM[[#This Row],[Department]], Lists!$L$4:$M$7, 2, FALSE), "") -> Amri, Abdulrahman A | BC37: Scraper Area Checklist | BD37: Monthly | BE37: October | BF37: A | BG37: FALSE
E38: =$S$3 -> South_Service | F38: =IFERROR(VLOOKUP(SSR[[#This Row],[Department]], Lists!$L$4:$M$7, 2, FALSE), "") -> Amri, Abdulrahman A | G38: ANSI | H38: 2025 | I38: November | J38: {=IFERROR( LOOKUP( 2,1/( ('Total Annual Points'!$B$5:$B$1000=E38)* ('Total Annual Points'!$C$5:$C$1000=G38)* ('Total Annual Points'!$D$5:$D$1000=H38)* (MATCH('Total Annual Points'!$E$5:$E$1000,{"January","February","March","April","May","June","July","August","September","October","November","December"},0) <=MATCH(I38,{"January","February","March","April","May","June","July","August","September","October","November","December"},0)) ), 'Total Annual Points'!$F$5:$F$1000 ), "")} | M38: =South_Service!$K38-South_Service!$L38 -> 0 | AC38: =$S$3 -> South_Service | AD38: =IFERROR(VLOOKUP(SSW[[#This Row],[Department]], Lists!$L$4:$M$7, 2, FALSE), "") -> Amri, Abdulrahman A | AE38: Chemical Inventory | AF38: Weekly | AG38: WK-23 | AH38: C | AI38: FALSE | BA38: =$S$3 -> South_Service | BB38: =IFERROR(VLOOKUP(SSM[[#This Row],[Department]], Lists!$L$4:$M$7, 2, FALSE), "") -> Amri, Abdulrahman A | BC38: Scraper Area Checklist | BD38: Monthly | BE38: November | BF38: B | BG38: FALSE
E39: =$S$3 -> South_Service | F39: =IFERROR(VLOOKUP(SSR[[#This Row],[Department]], Lists!$L$4:$M$7, 2, FALSE), "") -> Amri, Abdulrahman A | G39: ANSI | H39: 2025 | I39: December | J39: {=IFERROR( LOOKUP( 2,1/( ('Total Annual Points'!$B$5:$B$1000=E39)* ('Total Annual Points'!$C$5:$C$1000=G39)* ('Total Annual Points'!$D$5:$D$1000=H39)* (MATCH('Total Annual Points'!$E$5:$E$1000,{"January","February","March","April","May","June","July","August","September","October","November","December"},0) <=MATCH(I39,{"January","February","March","April","May","June","July","August","September","October","November","December"},0)) ), 'Total Annual Points'!$F$5:$F$1000 ), "")} | M39: =South_Service!$K39-South_Service!$L39 -> 0 | AC39: =$S$3 -> South_Service | AD39: =IFERROR(VLOOKUP(SSW[[#This Row],[Department]], Lists!$L$4:$M$7, 2, FALSE), "") -> Amri, Abdulrahman A | AE39: Chemical Inventory | AF39: Weekly | AG39: WK-24 | AH39: A | AI39: FALSE | BA39: =$S$3 -> South_Service | BB39: =IFERROR(VLOOKUP(SSM[[#This Row],[Department]], Lists!$L$4:$M$7, 2, FALSE), "") -> Amri, Abdulrahman A | BC39: Scraper Area Checklist | BD39: Monthly | BE39: December | BF39: C | BG39: FALSE
E40: =$S$3 -> South_Service | F40: =IFERROR(VLOOKUP(SSR[[#This Row],[Department]], Lists!$L$4:$M$7, 2, FALSE), "") -> Amri, Abdulrahman A | G40: Scraper | H40: 2025 | I40: January | J40: {=IFERROR( LOOKUP( 2,1/( ('Total Annual Points'!$B$5:$B$1000=E40)* ('Total Annual Points'!$C$5:$C$1000=G40)* ('Total Annual Points'!$D$5:$D$1000=H40)* (MATCH('Total Annual Points'!$E$5:$E$1000,{"January","February","March","April","May","June","July","August","September","October","November","December"},0) <=MATCH(I40,{"January","February","March","April","May","June","July","August","September","October","November","December"},0)) ), 'Total Annual Points'!$F$5:$F$1000 ), "")} | M40: =South_Service!$K40-South_Service!$L40 -> 0 | AC40: =$S$3 -> South_Service | AD40: =IFERROR(VLOOKUP(SSW[[#This Row],[Department]], Lists!$L$4:$M$7, 2, FALSE), "") -> Amri, Abdulrahman A | AE40: Chemical Inventory | AF40: Weekly | AG40: WK-25 | AH40: B | AI40: FALSE | BA40: =$S$3 -> South_Service | BB40: =IFERROR(VLOOKUP(SSM[[#This Row],[Department]], Lists!$L$4:$M$7, 2, FALSE), "") -> Amri, Abdulrahman A | BC40: Scraper PZV & Car Seal | BD40: Monthly | BE40: January | BF40: A | BG40: FALSE
E41: =$S$3 -> South_Service | F41: =IFERROR(VLOOKUP(SSR[[#This Row],[Department]], Lists!$L$4:$M$7, 2, FALSE), "") -> Amri, Abdulrahman A | G41: Scraper | H41: 2025 | I41: February | J41: {=IFERROR( LOOKUP( 2,1/( ('Total Annual Points'!$B$5:$B$1000=E41)* ('Total Annual Points'!$C$5:$C$1000=G41)* ('Total Annual Points'!$D$5:$D$1000=H41)* (MATCH('Total Annual Points'!$E$5:$E$1000,{"January","February","March","April","May","June","July","August","September","October","November","December"},0) <=MATCH(I41,{"January","February","March","April","May","June","July","August","September","October","November","December"},0)) ), 'Total Annual Points'!$F$5:$F$1000 ), "")} | M41: =South_Service!$K41-South_Service!$L41 -> 0 | AC41: =$S$3 -> South_Service | AD41: =IFERROR(VLOOKUP(SSW[[#This Row],[Department]], Lists!$L$4:$M$7, 2, FALSE), "") -> Amri, Abdulrahman A | AE41: Chemical Inventory | AF41: Weekly | AG41: WK-26 | AH41: C | AI41: FALSE | BA41: =$S$3 -> South_Service | BB41: =IFERROR(VLOOKUP(SSM[[#This Row],[Department]], Lists!$L$4:$M$7, 2, FALSE), "") -> Amri, Abdulrahman A | BC41: Scraper PZV & Car Seal | BD41: Monthly | BE41: February | BF41: B | BG41: FALSE
E42: =$S$3 -> South_Service | F42: =IFERROR(VLOOKUP(SSR[[#This Row],[Department]], Lists!$L$4:$M$7, 2, FALSE), "") -> Amri, Abdulrahman A | G42: Scraper | H42: 2025 | I42: March | J42: {=IFERROR( LOOKUP( 2,1/( ('Total Annual Points'!$B$5:$B$1000=E42)* ('Total Annual Points'!$C$5:$C$1000=G42)* ('Total Annual Points'!$D$5:$D$1000=H42)* (MATCH('Total Annual Points'!$E$5:$E$1000,{"January","February","March","April","May","June","July","August","September","October","November","December"},0) <=MATCH(I42,{"January","February","March","April","May","June","July","August","September","October","November","December"},0)) ), 'Total Annual Points'!$F$5:$F$1000 ), "")} | M42: =South_Service!$K42-South_Service!$L42 -> 0 | AC42: =$S$3 -> South_Service | AD42: =IFERROR(VLOOKUP(SSW[[#This Row],[Department]], Lists!$L$4:$M$7, 2, FALSE), "") -> Amri, Abdulrahman A | AE42: Chemical Inventory | AF42: Weekly | AG42: WK-27 | AH42: A | AI42: FALSE | BA42: =$S$3 -> South_Service | BB42: =IFERROR(VLOOKUP(SSM[[#This Row],[Department]], Lists!$L$4:$M$7, 2, FALSE), "") -> Amri, Abdulrahman A | BC42: Scraper PZV & Car Seal | BD42: Monthly | BE42: March | BF42: C | BG42: FALSE
E43: =$S$3 -> South_Service | F43: =IFERROR(VLOOKUP(SSR[[#This Row],[Department]], Lists!$L$4:$M$7, 2, FALSE), "") -> Amri, Abdulrahman A | G43: Scraper | H43: 2025 | I43: April | J43: {=IFERROR( LOOKUP( 2,1/( ('Total Annual Points'!$B$5:$B$1000=E43)* ('Total Annual Points'!$C$5:$C$1000=G43)* ('Total Annual Points'!$D$5:$D$1000=H43)* (MATCH('Total Annual Points'!$E$5:$E$1000,{"January","February","March","April","May","June","July","August","September","October","November","December"},0) <=MATCH(I43,{"January","February","March","April","May","June","July","August","September","October","November","December"},0)) ), 'Total Annual Points'!$F$5:$F$1000 ), "")} | M43: =South_Service!$K43-South_Service!$L43 -> 0 | AC43: =$S$3 -> South_Service | AD43: =IFERROR(VLOOKUP(SSW[[#This Row],[Department]], Lists!$L$4:$M$7, 2, FALSE), "") -> Amri, Abdulrahman A | AE43: Chemical Inventory | AF43: Weekly | AG43: WK-28 | AH43: B | AI43: FALSE | BA43: =$S$3 -> South_Service | BB43: =IFERROR(VLOOKUP(SSM[[#This Row],[Department]], Lists!$L$4:$M$7, 2, FALSE), "") -> Amri, Abdulrahman A | BC43: Scraper PZV & Car Seal | BD43: Monthly | BE43: April | BF43: A | BG43: FALSE
E44: =$S$3 -> South_Service | F44: =IFERROR(VLOOKUP(SSR[[#This Row],[Department]], Lists!$L$4:$M$7, 2, FALSE), "") -> Amri, Abdulrahman A | G44: Scraper | H44: 2025 | I44: May | J44: {=IFERROR( LOOKUP( 2,1/( ('Total Annual Points'!$B$5:$B$1000=E44)* ('Total Annual Points'!$C$5:$C$1000=G44)* ('Total Annual Points'!$D$5:$D$1000=H44)* (MATCH('Total Annual Points'!$E$5:$E$1000,{"January","February","March","April","May","June","July","August","September","October","November","December"},0) <=MATCH(I44,{"January","February","March","April","May","June","July","August","September","October","November","December"},0)) ), 'Total Annual Points'!$F$5:$F$1000 ), "")} | M44: =South_Service!$K44-South_Service!$L44 -> 0 | AC44: =$S$3 -> South_Service | AD44: =IFERROR(VLOOKUP(SSW[[#This Row],[Department]], Lists!$L$4:$M$7, 2, FALSE), "") -> Amri, Abdulrahman A | AE44: Chemical Inventory | AF44: Weekly | AG44: WK-29 | AH44: C | AI44: FALSE | BA44: =$S$3 -> South_Service | BB44: =IFERROR(VLOOKUP(SSM[[#This Row],[Department]], Lists!$L$4:$M$7, 2, FALSE), "") -> Amri, Abdulrahman A | BC44: Scraper PZV & Car Seal | BD44: Monthly | BE44: May | BF44: B | BG44: FALSE
... E51: =$S$3 -> South_Service | F51: =IFERROR(VLOOKUP(SSR[[#This Row],[Department]], Lists!$L$4:$M$7, 2, FALSE), "") -> Amri, Abdulrahman A | G51: Scraper | H51: 2025 | I51: December | J51: {=IFERROR( LOOKUP( 2,1/( ('Total Annual Points'!$B$5:$B$1000=E51)* ('Total Annual Points'!$C$5:$C$1000=G51)* ('Total Annual Points'!$D$5:$D$1000=H51)* (MATCH('Total Annual Points'!$E$5:$E$1000,{"January","February","March","April","May","June","July","August","September","October","November","December"},0) <=MATCH(I51,{"January","February","March","April","May","June","July","August","September","October","November","December"},0)) ), 'Total Annual Points'!$F$5:$F$1000 ), "")} | M51: =South_Service!$K51-South_Service!$L51 -> 0 | AC51: =$S$3 -> South_Service | AD51: =IFERROR(VLOOKUP(SSW[[#This Row],[Department]], Lists!$L$4:$M$7, 2, FALSE), "") -> Amri, Abdulrahman A | AE51: Chemical Inventory | AF51: Weekly | AG51: WK-36 | AH51: A | AI51: FALSE | BA51: =$S$3 -> South_Service | BB51: =IFERROR(VLOOKUP(SSM[[#This Row],[Department]], Lists!$L$4:$M$7, 2, FALSE), "") -> Amri, Abdulrahman A | BC51: Scraper PZV & Car Seal | BD51: Monthly | BE51: December | BF51: C | BG51: FALSE
E52: =$S$3 -> South_Service | F52: =IFERROR(VLOOKUP(SSR[[#This Row],[Department]], Lists!$L$4:$M$7, 2, FALSE), "") -> Amri, Abdulrahman A | G52: SSSV | H52: 2025 | I52: January | J52: {=IFERROR( LOOKUP( 2,1/( ('Total Annual Points'!$B$5:$B$1000=E52)* ('Total Annual Points'!$C$5:$C$1000=G52)* ('Total Annual Points'!$D$5:$D$1000=H52)* (MATCH('Total Annual Points'!$E$5:$E$1000,{"January","February","March","April","May","June","July","August","September","October","November","December"},0) <=MATCH(I52,{"January","February","March","April","May","June","July","August","September","October","November","December"},0)) ), 'Total Annual Points'!$F$5:$F$1000 ), "")} | M52: =South_Service!$K52-South_Service!$L52 -> 0 | AC52: =$S$3 -> South_Service | AD52: =IFERROR(VLOOKUP(SSW[[#This Row],[Department]], Lists!$L$4:$M$7, 2, FALSE), "") -> Amri, Abdulrahman A | AE52: Chemical Inventory | AF52: Weekly | AG52: WK-37 | AH52: B | AI52: FALSE | BA52: =$S$3 -> South_Service | BB52: =IFERROR(VLOOKUP(SSM[[#This Row],[Department]], Lists!$L$4:$M$7, 2, FALSE), "") -> Amri, Abdulrahman A | BG52: FALSE
E53: =$S$3 -> South_Service | F53: =IFERROR(VLOOKUP(SSR[[#This Row],[Department]], Lists!$L$4:$M$7, 2, FALSE), "") -> Amri, Abdulrahman A | G53: SSSV | H53: 2025 | I53: February | J53: {=IFERROR( LOOKUP( 2,1/( ('Total Annual Points'!$B$5:$B$1000=E53)* ('Total Annual Points'!$C$5:$C$1000=G53)* ('Total Annual Points'!$D$5:$D$1000=H53)* (MATCH('Total Annual Points'!$E$5:$E$1000,{"January","February","March","April","May","June","July","August","September","October","November","December"},0) <=MATCH(I53,{"January","February","March","April","May","June","July","August","September","October","November","December"},0)) ), 'Total Annual Points'!$F$5:$F$1000 ), "")} | M53: =South_Service!$K53-South_Service!$L53 -> 0 | AC53: =$S$3 -> South_Service | AD53: =IFERROR(VLOOKUP(SSW[[#This Row],[Department]], Lists!$L$4:$M$7, 2, FALSE), "") -> Amri, Abdulrahman A | AE53: Chemical Inventory | AF53: Weekly | AG53: WK-38 | AH53: C | AI53: FALSE | BA53: =$S$3 -> South_Service | BB53: =IFERROR(VLOOKUP(SSM[[#This Row],[Department]], Lists!$L$4:$M$7, 2, FALSE), "")
E54: =$S$3 -> South_Service | F54: =IFERROR(VLOOKUP(SSR[[#This Row],[Department]], Lists!$L$4:$M$7, 2, FALSE), "") -> Amri, Abdulrahman A | G54: SSSV | H54: 2025 | I54: March | J54: {=IFERROR( LOOKUP( 2,1/( ('Total Annual Points'!$B$5:$B$1000=E54)* ('Total Annual Points'!$C$5:$C$1000=G54)* ('Total Annual Points'!$D$5:$D$1000=H54)* (MATCH('Total Annual Points'!$E$5:$E$1000,{"January","February","March","April","May","June","July","August","September","October","November","December"},0) <=MATCH(I54,{"January","February","March","April","May","June","July","August","September","October","November","December"},0)) ), 'Total Annual Points'!$F$5:$F$1000 ), "")} | M54: =South_Service!$K54-South_Service!$L54 -> 0 | AC54: =$S$3 -> South_Service | AD54: =IFERROR(VLOOKUP(SSW[[#This Row],[Department]], Lists!$L$4:$M$7, 2, FALSE), "") -> Amri, Abdulrahman A | AE54: Chemical Inventory | AF54: Weekly | AG54: WK-39 | AH54: A | AI54: FALSE | BA54: =$S$3 -> South_Service | BB54: =IFERROR(VLOOKUP(SSM[[#This Row],[Department]], Lists!$L$4:$M$7, 2, FALSE), "")
E55: =$S$3 -> South_Service | F55: =IFERROR(VLOOKUP(SSR[[#This Row],[Department]], Lists!$L$4:$M$7, 2, FALSE), "") -> Amri, Abdulrahman A | G55: SSSV | H55: 2025 | I55: April | J55: {=IFERROR( LOOKUP( 2,1/( ('Total Annual Points'!$B$5:$B$1000=E55)* ('Total Annual Points'!$C$5:$C$1000=G55)* ('Total Annual Points'!$D$5:$D$1000=H55)* (MATCH('Total Annual Points'!$E$5:$E$1000,{"January","February","March","April","May","June","July","August","September","October","November","December"},0) <=MATCH(I55,{"January","February","March","April","May","June","July","August","September","October","November","December"},0)) ), 'Total Annual Points'!$F$5:$F$1000 ), "")} | M55: =South_Service!$K55-South_Service!$L55 -> 0 | AC55: =$S$3 -> South_Service | AD55: =IFERROR(VLOOKUP(SSW[[#This Row],[Department]], Lists!$L$4:$M$7, 2, FALSE), "") -> Amri, Abdulrahman A | AE55: Chemical Inventory | AF55: Weekly | AG55: WK-40 | AH55: B | AI55: FALSE | BA55: =$S$3 -> South_Service | BB55: =IFERROR(VLOOKUP(SSM[[#This Row],[Department]], Lists!$L$4:$M$7, 2, FALSE), "")
E56: =$S$3 -> South_Service | F56: =IFERROR(VLOOKUP(SSR[[#This Row],[Department]], Lists!$L$4:$M$7, 2, FALSE), "") -> Amri, Abdulrahman A | G56: SSSV | H56: 2025 | I56: May | J56: {=IFERROR( LOOKUP( 2,1/( ('Total Annual Points'!$B$5:$B$1000=E56)* ('Total Annual Points'!$C$5:$C$1000=G56)* ('Total Annual Points'!$D$5:$D$1000=H56)* (MATCH('Total Annual Points'!$E$5:$E$1000,{"January","February","March","April","May","June","July","August","September","October","November","December"},0) <=MATCH(I56,{"January","February","March","April","May","June","July","August","September","October","November","December"},0)) ), 'Total Annual Points'!$F$5:$F$1000 ), "")} | M56: =South_Service!$K56-South_Service!$L56 -> 0 | AC56: =$S$3 -> South_Service | AD56: =IFERROR(VLOOKUP(SSW[[#This Row],[Department]], Lists!$L$4:$M$7, 2, FALSE), "") -> Amri, Abdulrahman A | AE56: Chemical Inventory | AF56: Weekly | AG56: WK-41 | AH56: C | AI56: FALSE
E57: =$S$3 -> South_Service | F57: =IFERROR(VLOOKUP(SSR[[#This Row],[Department]], Lists!$L$4:$M$7, 2, FALSE), "") -> Amri, Abdulrahman A | G57: SSSV | H57: 2025 | I57: June | J57: {=IFERROR( LOOKUP( 2,1/( ('Total Annual Points'!$B$5:$B$1000=E57)* ('Total Annual Points'!$C$5:$C$1000=G57)* ('Total Annual Points'!$D$5:$D$1000=H57)* (MATCH('Total Annual Points'!$E$5:$E$1000,{"January","February","March","April","May","June","July","August","September","October","November","December"},0) <=MATCH(I57,{"January","February","March","April","May","June","July","August","September","October","November","December"},0)) ), 'Total Annual Points'!$F$5:$F$1000 ), "")} | M57: =South_Service!$K57-South_Service!$L57 -> 0 | AC57: =$S$3 -> South_Service | AD57: =IFERROR(VLOOKUP(SSW[[#This Row],[Department]], Lists!$L$4:$M$7, 2, FALSE), "") -> Amri, Abdulrahman A | AE57: Chemical Inventory | AF57: Weekly | AG57: WK-42 | AH57: A | AI57: FALSE
E58: =$S$3 -> South_Service | F58: =IFERROR(VLOOKUP(SSR[[#This Row],[Department]], Lists!$L$4:$M$7, 2, FALSE), "") -> Amri, Abdulrahman A | G58: SSSV | H58: 2025 | I58: July | J58: {=IFERROR( LOOKUP( 2,1/( ('Total Annual Points'!$B$5:$B$1000=E58)* ('Total Annual Points'!$C$5:$C$1000=G58)* ('Total Annual Points'!$D$5:$D$1000=H58)* (MATCH('Total Annual Points'!$E$5:$E$1000,{"January","February","March","April","May","June","July","August","September","October","November","December"},0) <=MATCH(I58,{"January","February","March","April","May","June","July","August","September","October","November","December"},0)) ), 'Total Annual Points'!$F$5:$F$1000 ), "")} | M58: =South_Service!$K58-South_Service!$L58 -> 0 | AC58: =$S$3 -> South_Service | AD58: =IFERROR(VLOOKUP(SSW[[#This Row],[Department]], Lists!$L$4:$M$7, 2, FALSE), "") -> Amri, Abdulrahman A | AE58: Chemical Inventory | AF58: Weekly | AG58: WK-43 | AH58: B | AI58: FALSE
...

Sheet North_Service
S2: =IFERROR(VLOOKUP(E16, Lists!$L$4:$M$7, 2, FALSE), "") -> Ghamdi, Anas K
S3: North_Service
E15: Department | F15: Manager | G15: Requirement | H15: Year | I15: Month | J15: Total Annual Points | K15: Monthly Target | L15: Completed | M15: Pending | N15: Notes | AC15: Department | AD15: Manager | AE15: Task | AF15: Frequancy | AG15: Period | AH15: Group | AI15: Completed (✔/✖) | AJ15: Notes | BA15: Department | BB15: Manager | BC15: Task | BD15: Frequancy | BE15: Period | BF15: Group | BG15: Completed (✔/✖) | BH15: Notes | BW15: Department | BX15: Manager | BY15: Task | BZ15: Frequancy | CA15: Period | CB15: Group | CC15: Completed (✔/✖) | CD15: Notes
E16: =$S$3 -> North_Service | F16: =IFERROR(VLOOKUP(NSR[[#This Row],[Department]], Lists!$L$4:$M$7, 2, FALSE), "") -> Ghamdi, Anas K | G16: ANNLI | H16: 2025 | I16: January | J16: {=IFERROR( LOOKUP( 2,1/( ('Total Annual Points'!$B$5:$B$1000=E16)* ('Total Annual Points'!$C$5:$C$1000=G16)* ('Total Annual Points'!$D$5:$D$1000=H16)* (MATCH('Total Annual Points'!$E$5:$E$1000,{"January","February","March","April","May","June","July","August","September","October","November","December"},0) <=MATCH(I16,{"January","February","March","April","May","June","July","August","September","October","November","December"},0)) ), 'Total Annual Points'!$F$5:$F$1000 ), "")} | M16: =North_Service!$K16-North_Service!$L16 -> 0 | AC16: =$S$3 -> North_Service | AD16: =IFERROR(VLOOKUP(NSW[[#This Row],[Department]], Lists!$L$4:$M$7, 2, FALSE), "") -> Ghamdi, Anas K | AE16: Chemical Inventory | AF16: Weekly | AG16: WK-1 | AH16: A | AI16: FALSE | BA16: =$S$3 -> North_Service | BB16: =IFERROR(VLOOKUP(NSM[[#This Row],[Department]], Lists!$L$4:$M$7, 2, FALSE), "") -> Ghamdi, Anas K | BC16: Fire Monitor & Hose Reel | BD16: Monthly | BE16: January | BF16: A | BG16: FALSE | BW16: =$S$3 -> North_Service | BX16: =IFERROR(VLOOKUP(NSQ[[#This Row],[Department]], Lists!$L$4:$M$7, 2, FALSE), "") -> Ghamdi, Anas K | BY16: Hoist Crane | BZ16: Quarterly | CA16: 1st Quarter | CB16: A | CC16: FALSE
E17: =$S$3 -> North_Service | F17: =IFERROR(VLOOKUP(NSR[[#This Row],[Department]], Lists!$L$4:$M$7, 2, FALSE), "") -> Ghamdi, Anas K | G17: ANNLI | H17: 2025 | I17: February | J17: {=IFERROR( LOOKUP( 2,1/( ('Total Annual Points'!$B$5:$B$1000=E17)* ('Total Annual Points'!$C$5:$C$1000=G17)* ('Total Annual Points'!$D$5:$D$1000=H17)* (MATCH('Total Annual Points'!$E$5:$E$1000,{"January","February","March","April","May","June","July","August","September","October","November","December"},0) <=MATCH(I17,{"January","February","March","April","May","June","July","August","September","October","November","December"},0)) ), 'Total Annual Points'!$F$5:$F$1000 ), "")} | M17: =North_Service!$K17-North_Service!$L17 -> 0 | AC17: =$S$3 -> North_Service | AD17: =$S$2 -> Ghamdi, Anas K | AE17: Chemical Inventory | AF17: Weekly | AG17: WK-2 | AH17: B | AI17: FALSE | BA17: =$S$3 -> North_Service | BB17: =IFERROR(VLOOKUP(NSM[[#This Row],[Department]], Lists!$L$4:$M$7, 2, FALSE), "") -> Ghamdi, Anas K | BC17: Fire Monitor & Hose Reel | BD17: Monthly | BE17: February | BF17: B | BG17: FALSE | BW17: =$S$3 -> North_Service | BX17: =IFERROR(VLOOKUP(NSQ[[#This Row],[Department]], Lists!$L$4:$M$7, 2, FALSE), "") -> Ghamdi, Anas K | BY17: Hoist Crane | BZ17: Quarterly | CA17: 2nd Quarter | CB17: B | CC17: FALSE
E18: =$S$3 -> North_Service | F18: =IFERROR(VLOOKUP(NSR[[#This Row],[Department]], Lists!$L$4:$M$7, 2, FALSE), "") -> Ghamdi, Anas K | G18: ANNLI | H18: 2025 | I18: March | J18: {=IFERROR( LOOKUP( 2,1/( ('Total Annual Points'!$B$5:$B$1000=E18)* ('Total Annual Points'!$C$5:$C$1000=G18)* ('Total Annual Points'!$D$5:$D$1000=H18)* (MATCH('Total Annual Points'!$E$5:$E$1000,{"January","February","March","April","May","June","July","August","September","October","November","December"},0) <=MATCH(I18,{"January","February","March","April","May","June","July","August","September","October","November","December"},0)) ), 'Total Annual Points'!$F$5:$F$1000 ), "")} | M18: =North_Service!$K18-North_Service!$L18 -> 0 | AC18: =$S$3 -> North_Service | AD18: =$S$2 -> Ghamdi, Anas K | AE18: Chemical Inventory | AF18: Weekly | AG18: WK-3 | AH18: C | AI18: FALSE | BA18: =$S$3 -> North_Service | BB18: =IFERROR(VLOOKUP(NSM[[#This Row],[Department]], Lists!$L$4:$M$7, 2, FALSE), "") -> Ghamdi, Anas K | BC18: Fire Monitor & Hose Reel | BD18: Monthly | BE18: March | BF18: C | BG18: FALSE | BW18: =$S$3 -> North_Service | BX18: =IFERROR(VLOOKUP(NSQ[[#This Row],[Department]], Lists!$L$4:$M$7, 2, FALSE), "") -> Ghamdi, Anas K | BY18: Hoist Crane | BZ18: Quarterly | CA18: 3rd Quarter | CB18: C | CC18: FALSE
E19: =$S$3 -> North_Service | F19: =IFERROR(VLOOKUP(NSR[[#This Row],[Department]], Lists!$L$4:$M$7, 2, FALSE), "") -> Ghamdi, Anas K | G19: ANNLI | H19: 2025 | I19: April | J19: {=IFERROR( LOOKUP( 2,1/( ('Total Annual Points'!$B$5:$B$1000=E19)* ('Total Annual Points'!$C$5:$C$1000=G19)* ('Total Annual Points'!$D$5:$D$1000=H19)* (MATCH('Total Annual Points'!$E$5:$E$1000,{"January","February","March","April","May","June","July","August","September","October","November","December"},0) <=MATCH(I19,{"January","February","March","April","May","June","July","August","September","October","November","December"},0)) ), 'Total Annual Points'!$F$5:$F$1000 ), "")} | M19: =North_Service!$K19-North_Service!$L19 -> 0 | AC19: =$S$3 -> North_Service | AD19: =$S$2 -> Ghamdi, Anas K | AE19: Chemical Inventory | AF19: Weekly | AG19: WK-4 | AH19: A | AI19: FALSE | BA19: =$S$3 -> North_Service | BB19: =IFERROR(VLOOKUP(NSM[[#This Row],[Department]], Lists!$L$4:$M$7, 2, FALSE), "") -> Ghamdi, Anas K | BC19: Fire Monitor & Hose Reel | BD19: Monthly | BE19: April | BF19: A | BG19: FALSE | BW19: =$S$3 -> North_Service | BX19: =IFERROR(VLOOKUP(NSQ[[#This Row],[Department]], Lists!$L$4:$M$7, 2, FALSE), "") -> Ghamdi, Anas K | BY19: Hoist Crane | BZ19: Quarterly | CA19: 4th Quarter | CB19: A | CC19: FALSE
E20: =$S$3 -> North_Service | F20: =IFERROR(VLOOKUP(NSR[[#This Row],[Department]], Lists!$L$4:$M$7, 2, FALSE), "") -> Ghamdi, Anas K | G20: ANNLI | H20: 2025 | I20: May | J20: {=IFERROR( LOOKUP( 2,1/( ('Total Annual Points'!$B$5:$B$1000=E20)* ('Total Annual Points'!$C$5:$C$1000=G20)* ('Total Annual Points'!$D$5:$D$1000=H20)* (MATCH('Total Annual Points'!$E$5:$E$1000,{"January","February","March","April","May","June","July","August","September","October","November","December"},0) <=MATCH(I20,{"January","February","March","April","May","June","July","August","September","October","November","December"},0)) ), 'Total Annual Points'!$F$5:$F$1000 ), "")} | M20: =North_Service!$K20-North_Service!$L20 -> 0 | AC20: =$S$3 -> North_Service | AD20: =$S$2 -> Ghamdi, Anas K | AE20: Chemical Inventory | AF20: Weekly | AG20: WK-5 | AH20: B | AI20: FALSE | BA20: =$S$3 -> North_Service | BB20: =IFERROR(VLOOKUP(NSM[[#This Row],[Department]], Lists!$L$4:$M$7, 2, FALSE), "") -> Ghamdi, Anas K | BC20: Fire Monitor & Hose Reel | BD20: Monthly | BE20: May | BF20: B | BG20: FALSE | BW20: =$S$3 -> North_Service | BX20: =IFERROR(VLOOKUP(NSQ[[#This Row],[Department]], Lists!$L$4:$M$7, 2, FALSE), "") -> Ghamdi, Anas K | BY20: Wind Sock | BZ20: Quarterly | CA20: 1st Quarter | CB20: A | CC20: FALSE
E21: =$S$3 -> North_Service | F21: =IFERROR(VLOOKUP(NSR[[#This Row],[Department]], Lists!$L$4:$M$7, 2, FALSE), "") -> Ghamdi, Anas K | G21: ANNLI | H21: 2025 | I21: June | J21: {=IFERROR( LOOKUP( 2,1/( ('Total Annual Points'!$B$5:$B$1000=E21)* ('Total Annual Points'!$C$5:$C$1000=G21)* ('Total Annual Points'!$D$5:$D$1000=H21)* (MATCH('Total Annual Points'!$E$5:$E$1000,{"January","February","March","April","May","June","July","August","September","October","November","December"},0) <=MATCH(I21,{"January","February","March","April","May","June","July","August","September","October","November","December"},0)) ), 'Total Annual Points'!$F$5:$F$1000 ), "")} | M21: =North_Service!$K21-North_Service!$L21 -> 0 | AC21: =$S$3 -> North_Service | AD21: =$S$2 -> Ghamdi, Anas K | AE21: Chemical Inventory | AF21: Weekly | AG21: WK-6 | AH21: C | AI21: FALSE | BA21: =$S$3 -> North_Service | BB21: =IFERROR(VLOOKUP(NSM[[#This Row],[Department]], Lists!$L$4:$M$7, 2, FALSE), "") -> Ghamdi, Anas K | BC21: Fire Monitor & Hose Reel | BD21: Monthly | BE21: June | BF21: C | BG21: FALSE | BW21: =$S$3 -> North_Service | BX21: =IFERROR(VLOOKUP(NSQ[[#This Row],[Department]], Lists!$L$4:$M$7, 2, FALSE), "") -> Ghamdi, Anas K | BY21: Wind Sock | BZ21: Quarterly | CA21: 2nd Quarter | CB21: B | CC21: FALSE
E22: =$S$3 -> North_Service | F22: =IFERROR(VLOOKUP(NSR[[#This Row],[Department]], Lists!$L$4:$M$7, 2, FALSE), "") -> Ghamdi, Anas K | G22: ANNLI | H22: 2025 | I22: July | J22: {=IFERROR( LOOKUP( 2,1/( ('Total Annual Points'!$B$5:$B$1000=E22)* ('Total Annual Points'!$C$5:$C$1000=G22)* ('Total Annual Points'!$D$5:$D$1000=H22)* (MATCH('Total Annual Points'!$E$5:$E$1000,{"January","February","March","April","May","June","July","August","September","October","November","December"},0) <=MATCH(I22,{"January","February","March","April","May","June","July","August","September","October","November","December"},0)) ), 'Total Annual Points'!$F$5:$F$1000 ), "")} | M22: =North_Service!$K22-North_Service!$L22 -> 0 | AC22: =$S$3 -> North_Service | AD22: =$S$2 -> Ghamdi, Anas K | AE22: Chemical Inventory | AF22: Weekly | AG22: WK-7 | AH22: A | AI22: FALSE | BA22: =$S$3 -> North_Service | BB22: =IFERROR(VLOOKUP(NSM[[#This Row],[Department]], Lists!$L$4:$M$7, 2, FALSE), "") -> Ghamdi, Anas K | BC22: Fire Monitor & Hose Reel | BD22: Monthly | BE22: July | BF22: A | BG22: FALSE | BW22: =$S$3 -> North_Service | BX22: =IFERROR(VLOOKUP(NSQ[[#This Row],[Department]], Lists!$L$4:$M$7, 2, FALSE), "") -> Ghamdi, Anas K | BY22: Wind Sock | BZ22: Quarterly | CA22: 3rd Quarter | CB22: C | CC22: FALSE
